<?xml version="1.0"?>
<robot name="motor_urdf" xmlns:xacro="http://ros.org/wiki/xacro">

  <xacro:property name="width" value="0.2" />
  <xacro:property name="leglen" value="0.6" />
  <xacro:property name="polelen" value="0.2" />
  <xacro:property name="bodylen" value="0.6" />
  <xacro:property name="baselen" value="0.4" />
  <xacro:property name="wheeldiam" value="0.07" />
  <xacro:property name="pi" value="3.1415" />

  <xacro:macro name="default_inertial" params="mass">
    <inertial>
      <mass value="${mass}" />
      <inertia ixx="1.0" ixy="0.0" ixz="0.0" iyy="1.0" iyz="0.0" izz="1.0" />
    </inertial>
  </xacro:macro>

  <xacro:macro name="motor_control" params="">
    <gazebo>
      <plugin name="motor_control" filename="libgazebo_ros_planar_move.so">
        <commandTopic>cmd_vel</commandTopic>
        <odometryTopic>odom</odometryTopic>
        <odometryFrame>odom</odometryFrame>
        <odometryRate>20.0</odometryRate>
        <robotBaseFrame>base_footprint</robotBaseFrame>
      </plugin>
    </gazebo>
  </xacro:macro>

  <link name="base_link">
    <visual>
    <origin rpy="1.57075 0 0" xyz="0 0 0"/>
      <geometry>
        <cylinder radius="${width}" length="${bodylen}"/>
      </geometry>
    </visual>
    <collision>
      <geometry>
        <cylinder radius="${width}" length="${bodylen}"/>
      </geometry>
    </collision>
    <xacro:default_inertial mass="10"/>
  </link>

  <link name="right_leg">
    <visual>
      <geometry>
        <box size="0.6 0.1 0.2"/>
      </geometry>
      <origin rpy="0 1.57075 0" xyz="0 0 -0.3"/>
    </visual>
    <collision>
      <geometry>
        <box size="0.6 0.1 0.2"/>
      </geometry>
      <origin rpy="0 1.57075 0" xyz="0 0 -0.3"/>
    </collision>
    <inertial>
      <mass value="10"/>
      <inertia ixx="1.0" ixy="0.0" ixz="0.0" iyy="1.0" iyz="0.0" izz="1.0"/>
    </inertial>
  </link>

  <joint name="base_to_right_leg" type="continuous">
    <axis rpy="0 0 0" xyz="0 1 0"/>
    <parent link="right_leg"/>
    <child link="base_link"/>
    <origin xyz="0 0 0.25"/>
  </joint>

  <xacro:motor_control/>


  <!-- This block connects the wheel joint to an actuator (motor), which informs both
  simulation and visualization of the robot -->
  <transmission name="motor_trans">
    <type>transmission_interface/SimpleTransmission</type>
    <actuator name="wheel_motor">
      <mechanicalReduction>1</mechanicalReduction>
    </actuator>
    <joint name="base_to_right_leg">
      <hardwareInterface>VelocityJointInterface</hardwareInterface>
    </joint>
  </transmission>

  <gazebo>
    <plugin name="gazebo_ros_control" filename="libgazebo_ros_control.so">
      <robotNamespace>/</robotNamespace>
    </plugin>
  </gazebo>

</robot>